Workbook

Sheet Sheet3
C5: Android Device indication No. | D5: 1.Pre-Sterilization position | E5: 2.Matching system | F5: Remark
C6: 1.S/N : 22340523020148 | D6: 〇 | E6: 〇 | F6: New device
C7: 2.S/N : 21336523021959 | E7: 〇 | F7: Old device (The Android device already has the Check Basket Position_V2 application installed.)
C8: 3
C9: 4
C10: 5
C11: 6
C12: 7
C13: 8
C14: 9
C15: 10

Sheet Sheet4
A3: Factory | B3: Currently | C3: Plan | D3: Next plan 5 devices
A4: N2 | B4: 1.Check Basket Position_V2 | C4: 2.Matching system | D4: 1.Check Basket Position_V2 + 2.Matching system
A16: Medical | B16: - | C16: 1.Check_basket_position_medical_V1 2.Matching system | D16: Next plan 10 devices (Check_basket_position_medical_V1+Matching system)

Sheet Sheet1
B2: product label 1 60/70
C3: JN-6426 | D3: JN-6427 | E3: JN-6428 | F3: JN-6429 | G3: JN-6430 | H3: JN-6431
B6: product label 1 50/70
C7: JN-6420 | D7: JN-6421 | E7: JN-6422 | F7: JN-6423 | G7: JN-6424 | H7: JN-6425
C9: Jig For Label Attach 4 Lens( PCI GW) 68/105
C10: JN-6432 | D10: JN-6433 | E10: JN-6434 | F10: JN-6435
C15: Jig For Label Attach (Soutenir & Streaming )55/65 | E15: JN-6437 | F15: Jig For Label Attach (Soutenir & Streaming )55/65
C16: JN-6436 | D16: JN-6437
C18: Jig For Label Attach (Ptca Gw ) CTO 24/5
C19: JN-4503 | D19: JN-5418 | E19: JN-5419 | F19: JN-5420 | G19: JN-5422

Sheet PTCA Packing 1
A1: Item SAP | B1: Item Code | C1: Name | D1: Dwg no. | E1: Doc. no. | F1: Japan doc No. | G1: Master SOP | H1: Product DWG No. | I1: SOP PRODUCT DRAWING | J1: Label check sheet for bag | K1: Label check sheet for box | L1: Label check sheet dilator for bag | M1: Label check sheet dilator for box | N1: Label check sheet Barcode Bag | O1: Label check sheet Barcode Box | P1: Label check sheet Barcode Dilator for bag | Q1: Label check sheet Barcode Dilator for box | T1: Label check sheet 4 Lens CN (bag) | U1: Label check sheet for distributor CN (box) | V1: Label check sheet distributor KR | W1: Label check sheet Accessories | X1: Drawing List no. Dilator & Barcode | Y1: Base Jig 1 | Z1: Base Jig 2 | AA1: Base Jig 3 | AB1: Base Jig 4 | AC1: Base Jig 5 | AD1: Base Jig 6 | AE1: Jig attach product label 1 | AF1: Jig attach product label 2 | AG1: Jig attach product label 3 | AH1: Jig attach product label 1 | AI1: Jig attach product label 2 | AJ1: Jig attach product label 3 | AK1: Jig attach other label 1 | AL1: Jig attach other label 2 | AM1: Jig attach other label 3 | AN1: Jig attach other label 1 | AO1: Jig attach other label 2 | AP1: Jig attach other label 3 | AQ1: Size | AR1: Product
A2: 11103260 | B2: 656001-S-A | C2: Streaming 14 135cm | D2: 1935046-0 | E2: ATN-19206 | F2: AMT3-099-009 | G2: ATN-18876 | H2: 1832365-0 | I2: ATN-19444 | J2: ATN-9877 | K2: ATN-9877 | M2: 55 | N2: 65 | O2: - | P2: - | R2: - | T2: - | U2: - | V2: - | Y2: JN-6438 | Z2: JN-6439 | AA2: JN-6440 | AB2: JN-6441 | AC2: JN-6442 | AD2: JN-6443 | AE2: JN-6436 | AF2: JN-6437 | AR2: PTCA
A3: 11103259 | B3: 656002-S-A | C3: Streaming 14 165cm | D3: 1935046-0 | E3: ATN-19206 | F3: AMT3-099-009 | G3: ATN-18876 | H3: 1832364-0 | I3: ATN-19443 | J3: ATN-9878 | K3: ATN-9878 | M3: 55 | N3: 65 | O3: - | P3: - | R3: - | T3: - | U3: - | V3: - | Y3: JN-6438 | Z3: JN-6439 | AA3: JN-6440 | AB3: JN-6441 | AC3: JN-6442 | AD3: JN-6443 | AE3: JN-6436 | AF3: JN-6437 | AR3: PTCA
A4: 11103261 | B4: 656003-S-A | C4: Streaming 14 180cm | D4: 1935046-0 | E4: ATN-19206 | F4: AMT3-099-009 | G4: ATN-18876 | H4: 1832362-0 | I4: ATN-19441 | J4: ATN-9879 | K4: ATN-9879 | M4: 55 | N4: 65 | O4: - | P4: - | R4: - | T4: - | U4: - | V4: - | Y4: JN-6438 | Z4: JN-6439 | AA4: JN-6440 | AB4: JN-6441 | AC4: JN-6442 | AD4: JN-6443 | AE4: JN-6436 | AF4: JN-6437 | AR4: PTCA
A5: 11103265 | B5: 656007-S-A | C5: Streaming 18 165cm | D5: 1935047-0 | E5: ATN-19207 | F5: AMT3-099-009 | G5: ATN-18876 | H5: 1832179-0 | I5: ATN-19396 | J5: ATN-9883 | K5: ATN-9883 | M5: 55 | N5: 65 | O5: - | P5: - | R5: - | T5: - | U5: - | V5: - | Y5: JN-6438 | Z5: JN-6439 | AA5: JN-6440 | AB5: JN-6441 | AC5: JN-6442 | AD5: JN-6443 | AE5: JN-6436 | AF5: JN-6437 | AR5: PTCA
A6: 11103266 | B6: 656008-S-A | C6: Streaming 18 180cm | D6: 1935047-0 | E6: ATN-19207 | F6: AMT3-099-009 | G6: ATN-18876 | H6: 1832180-0 | I6: ATN-19397 | J6: ATN-9884 | K6: ATN-9884 | M6: 55 | N6: 65 | O6: - | P6: - | R6: - | T6: - | U6: - | V6: - | Y6: JN-6438 | Z6: JN-6439 | AA6: JN-6440 | AB6: JN-6441 | AC6: JN-6442 | AD6: JN-6443 | AE6: JN-6436 | AF6: JN-6437 | AR6: PTCA
A7: 11000955 | B7: 1931039-A-A | C7: ASAHI PTCA Guide Wire ASAHI SION blue ES 190cm | D7: 1935015-A | E7: ATN-19013 | F7: AMT3-099-008 | G7: ATN-18523 | H7: 1832206-0 | I7: ATN-19405 | J7: OHP-LS-14455 | K7: OHP-LS-14456 | M7: 50 | N7: 70 | O7: - | P7: - | R7: - | T7: OHP-LS-15448 | U7: OHP-LS-15449 | V7: - | Y7: JN-6438 | Z7: JN-6439 | AA7: JN-6440 | AB7: JN-6441 | AC7: JN-6442 | AD7: JN-6443 | AE7: JN-6420 | AF7: JN-6421 | AG7: JN-6422 | AH7: JN-6423 | AI7: JN-6424 | AJ7: JN-6425 | AR7: PTCA
A8: 11000913 | B8: 1931113-0-AK | C8: ASAHI Peripheral Guide Wire ASAHI Halberd18 Straight 300cm | D8: 1935021-0 | E8: ATN-19047 | F8: AMT3-099-009 | G8: ATN-18876 | H8: 1832294-0 | I8: ATN-19668 | J8: OHP-LS-8701 | K8: OHP-LS-8702 | M8: 60 | N8: 70 | O8: 68 | P8: 105 | R8: - | T8: OHP-LS-8773 | U8: OHP-LS-8774 | V8: - | Y8: JN-6438 | Z8: JN-6439 | AA8: JN-6440 | AB8: JN-6441 | AC8: JN-6442 | AD8: JN-6443 | AE8: JN-6426 | AF8: JN-6427 | AG8: JN-6428 | AH8: JN-6429 | AI8: JN-6430 | AJ8: JN-6431 | AK8: JN-6432 | AL8: JN-6433 | AM8: JN-6434 | AN8: JN-6435 | AR8: PTCA
A9: 11000912 | B9: 1931114-0-AK | C9: ASAHI Peripheral Guide Wire ASAHI Halberd18 Pre-shape 300cm | D9: 1935021-0 | E9: ATN-19047 | F9: AMT3-099-009 | G9: ATN-18876 | H9: 1832295-0 | I9: ATN-19669 | J9: OHP-LS-8703 | K9: OHP-LS-8704 | M9: 60 | N9: 70 | O9: 68 | P9: 105 | R9: - | T9: OHP-LS-8775 | U9: OHP-LS-8776 | V9: - | Y9: JN-6438 | Z9: JN-6439 | AA9: JN-6440 | AB9: JN-6441 | AC9: JN-6442 | AD9: JN-6443 | AE9: JN-6426 | AF9: JN-6427 | AG9: JN-6428 | AH9: JN-6429 | AI9: JN-6430 | AJ9: JN-6431 | AK9: JN-6432 | AL9: JN-6433 | AM9: JN-6434 | AN9: JN-6435 | AR9: PTCA
A10: 11000918 | B10: 1931108-0-A | C10: ASAHI Peripheral Guide Wire ASAHI Halberd14 Pre-shape 300cm | D10: 1935020-0 | E10: ATN-19045 | F10: AMT3-099-009 | G10: ATN-18876 | H10: 1832289-0 | I10: - | J10: OHP-LS-8691 | K10: OHP-LS-8692 | M10: 60 | N10: 70 | O10: 68 | P10: 105 | R10: - | T10: OHP-LS-8763 | U10: OHP-LS-8764 | V10: - | Y10: JN-6438 | Z10: JN-6439 | AA10: JN-6440 | AB10: JN-6441 | AC10: JN-6442 | AD10: JN-6443 | AE10: JN-6426 | AF10: JN-6427 | AG10: JN-6428 | AH10: JN-6429 | AI10: JN-6430 | AJ10: JN-6431 | AK10: JN-6432 | AL10: JN-6433 | AM10: JN-6434 | AN10: JN-6435 | AR10: PTCA
A11: 11000919 | B11: 1931107-0-A | C11: ASAHI Peripheral Guide Wire ASAHI Halberd14 Straight 300cm | D11: 1935020-0 | E11: ATN-19045 | F11: AMT3-099-009 | G11: ATN-18876 | H11: 1832288-0 | I11: - | J11: OHP-LS-8689 | K11: OHP-LS-8690 | M11: 60 | N11: 70 | O11: 68 | P11: 105 | R11: - | T11: OHP-LS-8761 | U11: OHP-LS-8762 | V11: - | Y11: JN-6438 | Z11: JN-6439 | AA11: JN-6440 | AB11: JN-6441 | AC11: JN-6442 | AD11: JN-6443 | AE11: JN-6426 | AF11: JN-6427 | AG11: JN-6428 | AH11: JN-6429 | AI11: JN-6430 | AJ11: JN-6431 | AK11: JN-6432 | AL11: JN-6433 | AM11: JN-6434 | AN11: JN-6435 | AR11: PTCA
A12: 11000917 | B12: 1931109-0-AK | C12: ASAHI Peripheral Guide Wire ASAHI Halberd18 Straight 200cm | D12: 1935021-0 | E12: ATN-19047 | F12: AMT3-099-009 | G12: ATN-18876 | H12: 1832290-0 | I12: ATN-19664 | J12: OHP-LS-8693 | K12: OHP-LS-8694 | M12: 60 | N12: 70 | O12: 68 | P12: 105 | R12: - | T12: OHP-LS-8765 | U12: OHP-LS-8766 | V12: - | Y12: JN-6438 | Z12: JN-6439 | AA12: JN-6440 | AB12: JN-6441 | AC12: JN-6442 | AD12: JN-6443 | AE12: JN-6426 | AF12: JN-6427 | AG12: JN-6428 | AH12: JN-6429 | AI12: JN-6430 | AJ12: JN-6431 | AK12: JN-6432 | AL12: JN-6433 | AM12: JN-6434 | AN12: JN-6435 | AR12: PTCA
A13: 11000920 | B13: 1931106-0-A | C13: ASAHI Peripheral Guide Wire ASAHI Halberd14 Pre-shape 235cm | D13: 1935020-0 | E13: ATN-19045 | F13: AMT3-099-009 | G13: ATN-18876 | H13: 1832287-0 | I13: - | J13: OHP-LS-8687 | K13: OHP-LS-8688 | M13: 60 | N13: 70 | O13: 68 | P13: 105 | R13: - | T13: OHP-LS-8759 | U13: OHP-LS-8760 | V13: - | Y13: JN-6438 | Z13: JN-6439 | AA13: JN-6440 | AB13: JN-6441 | AC13: JN-6442 | AD13: JN-6443 | AE13: JN-6426 | AF13: JN-6427 | AG13: JN-6428 | AH13: JN-6429 | AI13: JN-6430 | AJ13: JN-6431 | AK13: JN-6432 | AL13: JN-6433 | AM13: JN-6434 | AN13: JN-6435 | AR13: PTCA
A14: 11000916 | B14: 1931110-0-AK | C14: ASAHI Peripheral Guide Wire ASAHI Halberd18 Pre-shape 200cm | D14: 1935021-0 | E14: ATN-19047 | F14: AMT3-099-009 | G14: ATN-18876 | H14: 1832291-0 | I14: ATN-19665 | J14: OHP-LS-8695 | K14: OHP-LS-8696 | M14: 60 | N14: 70 | O14: 68 | P14: 105 | R14: - | T14: OHP-LS-8767 | U14: OHP-LS-8768 | V14: - | Y14: JN-6438 | Z14: JN-6439 | AA14: JN-6440 | AB14: JN-6441 | AC14: JN-6442 | AD14: JN-6443 | AE14: JN-6426 | AF14: JN-6427 | AG14: JN-6428 | AH14: JN-6429 | AI14: JN-6430 | AJ14: JN-6431 | AK14: JN-6432 | AL14: JN-6433 | AM14: JN-6434 | AN14: JN-6435 | AR14: PTCA
A15: 11000915 | B15: 1931111-0-AK | C15: ASAHI Peripheral Guide Wire ASAHI Halberd18 Straight 235cm | D15: 1935021-0 | E15: ATN-19047 | F15: AMT3-099-009 | G15: ATN-18876 | H15: 1832292-0 | I15: ATN-19666 | J15: OHP-LS-8697 | K15: OHP-LS-8698 | M15: 60 | N15: 70 | O15: 68 | P15: 105 | R15: - | T15: OHP-LS-8769 | U15: OHP-LS-8770 | V15: - | Y15: JN-6438 | Z15: JN-6439 | AA15: JN-6440 | AB15: JN-6441 | AC15: JN-6442 | AD15: JN-6443 | AE15: JN-6426 | AF15: JN-6427 | AG15: JN-6428 | AH15: JN-6429 | AI15: JN-6430 | AJ15: JN-6431 | AK15: JN-6432 | AL15: JN-6433 | AM15: JN-6434 | AN15: JN-6435 | AR15: PTCA
A16: 11000914 | B16: 1931112-0-AK | C16: ASAHI Peripheral Guide Wire ASAHI Halberd18 Pre-shape 235cm | D16: 1935021-0 | E16: ATN-19047 | F16: AMT3-099-009 | G16: ATN-18876 | H16: 1832293-0 | I16: ATN-19667 | J16: OHP-LS-8699 | K16: OHP-LS-8700 | M16: 60 | N16: 70 | O16: 68 | P16: 105 | R16: - | T16: OHP-LS-8771 | U16: OHP-LS-8772 | V16: - | Y16: JN-6438 | Z16: JN-6439 | AA16: JN-6440 | AB16: JN-6441 | AC16: JN-6442 | AD16: JN-6443 | AE16: JN-6426 | AF16: JN-6427 | AG16: JN-6428 | AH16: JN-6429 | AI16: JN-6430 | AJ16: JN-6431 | AK16: JN-6432 | AL16: JN-6433 | AM16: JN-6434 | AN16: JN-6435 | AR16: PTCA
A17: 11003330 | B17: 1731086-C-AK | C17: ASAHI PTCA Guide Wire FIELDER XT 300cm | D17: 1835109-A | E17: ATN-19255 | F17: AMT3-099-008 | G17: ATN-18523 | H17: 1832212-0 | I17: ATN-19654 | J17: OHP-LS-8647 | K17: OHP-LS-8648 | M17: 50 | N17: 70 | O17: - | P17: - | R17: 24 | T17: - | U17: - | V17: - | Y17: JN-6438 | Z17: JN-6439 | AA17: JN-6440 | AB17: JN-6441 | AC17: JN-6442 | AD17: JN-6443 | AE17: JN-6420 | AF17: JN-6421 | AG17: JN-6422 | AH17: JN-6423 | AI17: JN-6424 | AJ17: JN-6425 | AK17: JN-4503 | AL17: JN-5418 | AM17: JN-5419 | AN17: JN-5420 | AO17: JN-5422 | AR17: PTCA
A18: 11000952 | B18: 1931042-A-A | C18: ASAHI PTCA Guide Wire ASAHI SION blue ES 300cm J | D18: 1935015-A | E18: ATN-19013 | F18: AMT3-099-008 | G18: ATN-18523 | H18: 1832210-0 | I18: ATN-19652 | J18: OHP-LS-14461 | K18: OHP-LS-14462 | M18: 50 | N18: 70 | O18: - | P18: - | R18: - | T18: OHP-LS-15454 | U18: OHP-LS-15455 | V18: - | Y18: JN-6438 | Z18: JN-6439 | AA18: JN-6440 | AB18: JN-6441 | AC18: JN-6442 | AD18: JN-6443 | AE18: JN-6420 | AF18: JN-6421 | AG18: JN-6422 | AH18: JN-6423 | AI18: JN-6424 | AJ18: JN-6425 | AR18: PTCA
A19: 11000953 | B19: 1931041-A-A | C19: ASAHI PTCA Guide Wire ASAHI SION blue ES 190cm J | D19: 1935015-A | E19: ATN-19013 | F19: AMT3-099-008 | G19: ATN-18523 | H19: 1832207-0 | I19: ATN-19650 | J19: OHP-LS-14459 | K19: OHP-LS-14460 | M19: 50 | N19: 70 | O19: - | P19: - | R19: - | T19: OHP-LS-15452 | U19: OHP-LS-15453 | V19: - | Y19: JN-6438 | Z19: JN-6439 | AA19: JN-6440 | AB19: JN-6441 | AC19: JN-6442 | AD19: JN-6443 | AE19: JN-6420 | AF19: JN-6421 | AG19: JN-6422 | AH19: JN-6423 | AI19: JN-6424 | AJ19: JN-6425 | AR19: PTCA
A20: 11000954 | B20: 1931040-A-A | C20: ASAHI PTCA Guide Wire ASAHI SION blue ES 300cm | D20: 1935015-A | E20: ATN-19013 | F20: AMT3-099-008 | G20: ATN-18523 | H20: 1832209-0 | I20: ATN-19651 | J20: OHP-LS-14457 | K20: OHP-LS-14458 | M20: 50 | N20: 70 | O20: - | P20: - | R20: - | T20: OHP-LS-15450 | U20: OHP-LS-15451 | V20: - | Y20: JN-6438 | Z20: JN-6439 | AA20: JN-6440 | AB20: JN-6441 | AC20: JN-6442 | AD20: JN-6443 | AE20: JN-6420 | AF20: JN-6421 | AG20: JN-6422 | AH20: JN-6423 | AI20: JN-6424 | AJ20: JN-6425 | AR20: PTCA
A21: 11000947 | B21: 1931082-0-AK | C21: ASAHI PTCA Guide Wire ASAHI Gaia Next 3 190cm Pre-shape | D21: 1935045-0 | E21: ATN-19830 | F21: AMT3-139-019 | G21: ATN-19834 | H21: 1932447-0 | I21: ATN-19855 | J21: OHP-LS-9436 | K21: OHP-LS-9437 | M21: 50 | N21: 70 | O21: - | P21: - | R21: 24 | T21: - | U21: - | V21: - | Y21: JN-6438 | Z21: JN-6439 | AA21: JN-6440 | AB21: JN-6441 | AC21: JN-6442 | AD21: JN-6443 | AE21: JN-6420 | AF21: JN-6421 | AG21: JN-6422 | AH21: JN-6423 | AI21: JN-6424 | AJ21: JN-6425 | AK21: JN-4503 | AL21: JN-5418 | AM21: JN-5419 | AN21: JN-5420 | AO21: JN-5422 | AR21: PTCA
A22: 11103435 | B22: 09B1001-J-AK | C22: Soutenir NV 3mm | D22: 1935050-0 | E22: ATN-21682 | F22: AMT10-001-007 | G22: ATN-21685 | H22: 1942149-0 | I22: ATN-20036 | J22: OHP-LS-12792 | K22: OHP-LS-12793 | M22: #N/A | N22: #N/A | O22: #N/A | P22: #N/A | R22: #N/A | T22: - | U22: - | V22: - | AR22: PTCA
A23: 11103433 | B23: 10B1003-D-AK | C23: Soutenir CV 7mm | D23: 1935048-0 | E23: ATN-21681 | F23: AMT10-001-007 | G23: ATN-21685 | H23: 1942151-0 | I23: ATN-20038 | J23: ATN-10374 | K23: ATN-10374 | M23: #N/A | N23: #N/A | O23: #N/A | P23: #N/A | R23: #N/A | T23: - | U23: - | V23: - | AR23: PTCA
A24: 11103434 | B24: 10B1004-D-AK | C24: Soutenir CV 3mm (Short type) | D24: 1935048-0 | E24: ATN-21681 | F24: AMT10-001-007 | G24: ATN-21685 | H24: 1942152-0 | I24: ATN-20039 | J24: ATN-10375 | K24: ATN-10375 | M24: #N/A | N24: #N/A | O24: #N/A | P24: #N/A | R24: #N/A | T24: - | U24: - | V24: - | AR24: PTCA
A25: 11103402 | B25: 10B1005-D-AK | C25: Soutenir CV 5mm (Short type) | D25: 1935048-0 | E25: ATN-21681 | F25: AMT10-001-007 | G25: ATN-21685 | H25: 1942153-0 | I25: ATN-20040 | J25: ATN-10376 | K25: ATN-10376 | M25: #N/A | N25: #N/A | O25: #N/A | P25: #N/A | R25: #N/A | T25: - | U25: - | V25: - | AR25: PTCA
A26: 11000945 | B26: 1931082-A-AK | C26: ASAHI PTCA Guide Wire ASAHI Gaia Next 3 190cm Pre-shape | D26: 1935045-0 | E26: ATN-19830 | F26: AMT3-139-019 | G26: ATN-19834 | H26: 2032052-0 | I26: ATN-22257 | J26: OHP-LS-9436 | K26: OHP-LS-9437 | M26: 50 | N26: 70 | O26: - | P26: - | R26: 24 | T26: - | U26: - | V26: - | Y26: JN-6438 | Z26: JN-6439 | AA26: JN-6440 | AB26: JN-6441 | AC26: JN-6442 | AD26: JN-6443 | AE26: JN-6420 | AF26: JN-6421 | AG26: JN-6422 | AH26: JN-6423 | AI26: JN-6424 | AJ26: JN-6425 | AK26: JN-4503 | AL26: JN-5418 | AM26: JN-5419 | AN26: JN-5420 | AO26: JN-5422 | AR26: PTCA
A27: 11015189 | B27: 1931027-0-A | C27: ASAHI PTCA Guide Wire ASAHI SION blue 190cm Pre-shape | D27: 1835104-A | E27: ATN-21444 | F27: AMT3-099-008 | G27: ATN-18523 | H27: 1932115-0 | I27: ATN-20772 | J27: OHP-LS-9618 | K27: OHP-LS-9619 | M27: 50 | N27: 70 | O27: - | P27: - | R27: - | T27: - | U27: - | V27: - | Y27: JN-6438 | Z27: JN-6439 | AA27: JN-6440 | AB27: JN-6441 | AC27: JN-6442 | AD27: JN-6443 | AE27: JN-6420 | AF27: JN-6421 | AG27: JN-6422 | AH27: JN-6423 | AI27: JN-6424 | AJ27: JN-6425 | AR27: PTCA
A28: 11000962 | B28: 1931029-0-AK | C28: ASAHI PTCA Guide Wire ASAHI SION 190cm Pre-shape | D28: 1835103-A | E28: ATN-21134 | F28: AMT3-099-008 | G28: ATN-18523 | H28: 1932107-0 | I28: ATN-20768 | J28: OHP-LS-9610 | K28: OHP-LS-9611 | M28: 50 | N28: 70 | O28: - | P28: - | R28: - | T28: - | U28: - | V28: - | Y28: JN-6438 | Z28: JN-6439 | AA28: JN-6440 | AB28: JN-6441 | AC28: JN-6442 | AD28: JN-6443 | AE28: JN-6420 | AF28: JN-6421 | AG28: JN-6422 | AH28: JN-6423 | AI28: JN-6424 | AJ28: JN-6425 | AR28: PTCA
A29: 11103122 | B29: 1731115-C-AK | C29: ASAHI PTCA Guide Wire ASAHI SION 180cm | D29: 1835103-A | E29: ATN-21134 | F29: AMT3-099-008 | G29: ATN-18523 | H29: 1832196-0 | I29: ATN-20019 | J29: OHP-LS-2288 | K29: OHP-LS-2289 | M29: 50 | N29: 70 | O29: - | P29: - | R29: - | T29: - | U29: - | V29: - | Y29: JN-6438 | Z29: JN-6439 | AA29: JN-6440 | AB29: JN-6441 | AC29: JN-6442 | AD29: JN-6443 | AE29: JN-6420 | AF29: JN-6421 | AG29: JN-6422 | AH29: JN-6423 | AI29: JN-6424 | AJ29: JN-6425 | AR29: PTCA
A30: 11015228 | B30: 1731116-C-AK | C30: ASAHI PTCA Guide Wire ASAHI SION 300cm | D30: 1835103-A | E30: ATN-21134 | F30: AMT3-099-008 | G30: ATN-18523 | H30: 1832195-0 | I30: ATN-20170 | J30: OHP-LS-2290 | K30: OHP-LS-2291 | M30: 50 | N30: 70 | O30: - | P30: - | R30: - | T30: - | U30: - | V30: - | Y30: JN-6438 | Z30: JN-6439 | AA30: JN-6440 | AB30: JN-6441 | AC30: JN-6442 | AD30: JN-6443 | AE30: JN-6420 | AF30: JN-6421 | AG30: JN-6422 | AH30: JN-6423 | AI30: JN-6424 | AJ30: JN-6425 | AR30: PTCA
A31: 11015227 | B31: 1731147-C-AK | C31: ASAHI PTCA Guide Wire ASAHI SION 180cm J | D31: 1835103-A | E31: ATN-21134 | F31: AMT3-099-008 | G31: ATN-18523 | H31: 1832197-0 | I31: ATN-20171 | J31: OHP-LS-2348 | K31: OHP-LS-2349 | M31: 50 | N31: 70 | O31: - | P31: - | R31: - | T31: - | U31: - | V31: - | Y31: JN-6438 | Z31: JN-6439 | AA31: JN-6440 | AB31: JN-6441 | AC31: JN-6442 | AD31: JN-6443 | AE31: JN-6420 | AF31: JN-6421 | AG31: JN-6422 | AH31: JN-6423 | AI31: JN-6424 | AJ31: JN-6425 | AR31: PTCA
A32: 11015226 | B32: 1731148-C-AK | C32: ASAHI PTCA Guide Wire ASAHI SION 300cm J | D32: 1835103-A | E32: ATN-21134 | F32: AMT3-099-008 | G32: ATN-18523 | H32: 1832198-0 | I32: ATN-20172 | J32: OHP-LS-2350 | K32: OHP-LS-2351 | M32: 50 | N32: 70 | O32: - | P32: - | R32: - | T32: - | U32: - | V32: - | Y32: JN-6438 | Z32: JN-6439 | AA32: JN-6440 | AB32: JN-6441 | AC32: JN-6442 | AD32: JN-6443 | AE32: JN-6420 | AF32: JN-6421 | AG32: JN-6422 | AH32: JN-6423 | AI32: JN-6424 | AJ32: JN-6425 | AR32: PTCA
A33: 11000963 | B33: 1931028-0-AK | C33: ASAHI PTCA Guide Wire ASAHI SION 300cm Pre-shape | D33: 1835103-A | E33: ATN-21134 | F33: AMT3-099-008 | G33: ATN-18523 | H33: 1932108-0 | I33: ATN-20769 | J33: OHP-LS-9612 | K33: OHP-LS-9613 | M33: 50 | N33: 70 | O33: - | P33: - | R33: - | T33: - | U33: - | V33: - | Y33: JN-6438 | Z33: JN-6439 | AA33: JN-6440 | AB33: JN-6441 | AC33: JN-6442 | AD33: JN-6443 | AE33: JN-6420 | AF33: JN-6421 | AG33: JN-6422 | AH33: JN-6423 | AI33: JN-6424 | AJ33: JN-6425 | AR33: PTCA
A34: 11000961 | B34: 1931030-0-AK | C34: ASAHI PTCA Guide Wire ASAHI SION 190cm | D34: 1835103-A | E34: ATN-21134 | F34: AMT3-099-008 | G34: ATN-18523 | H34: 1932105-0 | I34: ATN-20766 | J34: OHP-LS-9606 | K34: OHP-LS-9607 | M34: 50 | N34: 70 | O34: - | P34: - | R34: - | T34: - | U34: - | V34: - | Y34: JN-6438 | Z34: JN-6439 | AA34: JN-6440 | AB34: JN-6441 | AC34: JN-6442 | AD34: JN-6443 | AE34: JN-6420 | AF34: JN-6421 | AG34: JN-6422 | AH34: JN-6423 | AI34: JN-6424 | AJ34: JN-6425 | AR34: PTCA
A35: 11000960 | B35: 1931034-0-AK | C35: ASAHI PTCA Guide Wire ASAHI SION 190cm J | D35: 1835103-A | E35: ATN-21134 | F35: AMT3-099-008 | G35: ATN-18523 | H35: 1932106-0 | I35: ATN-20767 | J35: OHP-LS-9608 | K35: OHP-LS-9609 | M35: 50 | N35: 70 | O35: - | P35: - | R35: - | T35: - | U35: - | V35: - | Y35: JN-6438 | Z35: JN-6439 | AA35: JN-6440 | AB35: JN-6441 | AC35: JN-6442 | AD35: JN-6443 | AE35: JN-6420 | AF35: JN-6421 | AG35: JN-6422 | AH35: JN-6423 | AI35: JN-6424 | AJ35: JN-6425 | AR35: PTCA
A36: 11003228 | B36: 1731151-C-A | C36: ASAHI PTCA Guide Wire ASAHI SION blue 300cm | D36: 1835104-A | E36: ATN-21444 | F36: AMT3-099-008 | G36: ATN-18523 | H36: 1932111-0 | I36: ATN-20555 | J36: OHP-LS-2356 | K36: OHP-LS-2357 | M36: 50 | N36: 70 | O36: - | P36: - | R36: - | T36: - | U36: - | V36: - | Y36: JN-6438 | Z36: JN-6439 | AA36: JN-6440 | AB36: JN-6441 | AC36: JN-6442 | AD36: JN-6443 | AE36: JN-6420 | AF36: JN-6421 | AG36: JN-6422 | AH36: JN-6423 | AI36: JN-6424 | AJ36: JN-6425 | AR36: PTCA
A37: 11003226 | B37: 1731152-C-A | C37: ASAHI PTCA Guide Wire ASAHI SION blue 300cm J | D37: 1835104-A | E37: ATN-21444 | F37: AMT3-099-008 | G37: ATN-18523 | H37: 1932112-0 | I37: ATN-20556 | J37: OHP-LS-2358 | K37: OHP-LS-2359 | M37: 50 | N37: 70 | O37: - | P37: - | R37: - | T37: - | U37: - | V37: - | Y37: JN-6438 | Z37: JN-6439 | AA37: JN-6440 | AB37: JN-6441 | AC37: JN-6442 | AD37: JN-6443 | AE37: JN-6420 | AF37: JN-6421 | AG37: JN-6422 | AH37: JN-6423 | AI37: JN-6424 | AJ37: JN-6425 | AR37: PTCA
A38: 11015190 | B38: 1931024-0-A | C38: ASAHI PTCA Guide Wire ASAHI SION blue 300cm Pre-shape | D38: 1835104-A | E38: ATN-21444 | F38: AMT3-099-008 | G38: ATN-18523 | H38: 1932116-0 | I38: ATN-20773 | J38: OHP-LS-9620 | K38: OHP-LS-9621 | M38: 50 | N38: 70 | O38: - | P38: - | R38: - | T38: - | U38: - | V38: - | Y38: JN-6438 | Z38: JN-6439 | AA38: JN-6440 | AB38: JN-6441 | AC38: JN-6442 | AD38: JN-6443 | AE38: JN-6420 | AF38: JN-6421 | AG38: JN-6422 | AH38: JN-6423 | AI38: JN-6424 | AJ38: JN-6425 | AR38: PTCA
... A42: 11000522 | B42: 2031034-A-A | C42: ASAHI PTCA Guide Wire ASAHI Gladius EX14 300cm Pre-shape | D42: 2035007-A | E42: ATN-21671 | F42: AMT3-078-009 | G42: ATN-19777 | H42: 1932135-0 | I42: ATN-19451 | J42: OHP-LS-10035 | K42: OHP-LS-10036 | M42: 50 | N42: 70 | O42: - | P42: - | R42: - | T42: - | U42: - | V42: - | Y42: JN-6438 | Z42: JN-6439 | AA42: JN-6440 | AB42: JN-6441 | AC42: JN-6442 | AD42: JN-6443 | AE42: JN-6420 | AF42: JN-6421 | AG42: JN-6422 | AH42: JN-6423 | AI42: JN-6424 | AJ42: JN-6425 | AR42: PTCA
A43: 11005074 | B43: 1556112-E-A | C43: STREAMING 14 135CM | D43: 1835209-A | E43: ATN-22265 | F43: AMT3-099-009 | G43: ATN-18876 | H43: 1832365-0 | I43: ATN-19444 | J43: ATN-16802 | K43: ATN-16802 | M43: 55 | N43: 65 | O43: - | P43: - | R43: - | T43: - | U43: - | V43: OHP-LS-10445 | Y43: JN-6438 | Z43: JN-6439 | AA43: JN-6440 | AB43: JN-6441 | AC43: JN-6442 | AD43: JN-6443 | AE43: JN-6436 | AF43: JN-6437 | AR43: PTCA
...

Sheet PTCA Packing 2
A1: Item SAP | B1: Item Code | C1: Name | D1: Dwg no. | E1: Doc. no. | F1: Japan doc No. | G1: Master SOP | H1: Product
A2: 11103260 | B2: 656001-S-A | C2: Streaming 14 135cm | D2: 1935046-0 | E2: ATN-19213 | F2: AMT3-099-012 | G2: ATN-18877 | H2: PTCA
A3: 11103259 | B3: 656002-S-A | C3: Streaming 14 165cm | D3: 1935046-0 | E3: ATN-19213 | F3: AMT3-099-012 | G3: ATN-18877 | H3: PTCA
A4: 11103261 | B4: 656003-S-A | C4: Streaming 14 180cm | D4: 1935046-0 | E4: ATN-19213 | F4: AMT3-099-012 | G4: ATN-18877 | H4: PTCA
A5: 11103265 | B5: 656007-S-A | C5: Streaming 18 165cm | D5: 1935047-0 | E5: ATN-19214 | F5: AMT3-099-012 | G5: ATN-18877 | H5: PTCA
A6: 11103266 | B6: 656008-S-A | C6: Streaming 18 180cm | D6: 1935047-0 | E6: ATN-19214 | F6: AMT3-099-012 | G6: ATN-18877 | H6: PTCA
A7: 11000955 | B7: 1931039-A-A | C7: ASAHI PTCA Guide Wire ASAHI SION blue ES 190cm | D7: 1935015-A | E7: ATN-19014 | F7: AMT3-099-011 | G7: ATN-18524 | H7: PTCA
A8: 11000913 | B8: 1931113-0-AK | C8: ASAHI Peripheral Guide Wire ASAHI Halberd18 Straight 300cm | D8: 1935021-0 | E8: ATN-19048 | F8: AMT3-099-012 | G8: ATN-18877 | H8: PTCA
A9: 11000912 | B9: 1931114-0-AK | C9: ASAHI Peripheral Guide Wire ASAHI Halberd18 Pre-shape 300cm | D9: 1935021-0 | E9: ATN-19048 | F9: AMT3-099-012 | G9: ATN-18877 | H9: PTCA
A10: 11000918 | B10: 1931108-0-A | C10: ASAHI Peripheral Guide Wire ASAHI Halberd14 Pre-shape 300cm | D10: 1935020-0 | E10: ATN-19046 | F10: AMT3-099-012 | G10: ATN-18877 | H10: PTCA
A11: 11000919 | B11: 1931107-0-A | C11: ASAHI Peripheral Guide Wire ASAHI Halberd14 Straight 300cm | D11: 1935020-0 | E11: ATN-19046 | F11: AMT3-099-012 | G11: ATN-18877 | H11: PTCA
A12: 11000917 | B12: 1931109-0-AK | C12: ASAHI Peripheral Guide Wire ASAHI Halberd18 Straight 200cm | D12: 1935021-0 | E12: ATN-19048 | F12: AMT3-099-012 | G12: ATN-18877 | H12: PTCA
A13: 11000920 | B13: 1931106-0-A | C13: ASAHI Peripheral Guide Wire ASAHI Halberd14 Pre-shape 235cm | D13: 1935020-0 | E13: ATN-19046 | F13: AMT3-099-012 | G13: ATN-18877 | H13: PTCA
... A400: 11125790 | B400: 2031013-E-AK | C400: ASAHI Peripheral Guide Wire ASAHI Gladius MG14 PV ES 235cm Straight | D400: 2035005-D | E400: ATN-21675 | F400: AMT3-086-008 | G400: ATN-21132 | H400: PTCA
A401: 11125791 | B401: 2031014-E-AK | C401: ASAHI Peripheral Guide Wire ASAHI Gladius MG14 PV ES 235cm Pre-shape | D401: 2035005-D | E401: ATN-21675 | F401: AMT3-086-008 | G401: ATN-21132 | H401: PTCA
A402: 11125792 | B402: 2031015-E-AK | C402: ASAHI Peripheral Guide Wire ASAHI Gladius MG14 PV ES 300cm Straight | D402: 2035005-D | E402: ATN-21675 | F402: AMT3-086-008 | G402: ATN-21132 | H402: PTCA
A403: 11125793 | B403: 2031016-E-AK | C403: ASAHI Peripheral Guide Wire ASAHI Gladius MG14 PV ES 300cm Pre-shape | D403: 2035005-D | E403: ATN-21675 | F403: AMT3-086-008 | G403: ATN-21132 | H403: PTCA
A404: 11125794 | B404: 2031017-E-AK | C404: ASAHI Peripheral Guide Wire ASAHI Gladius MG18 PV ES 190cm Straight | D404: 2035006-D | E404: ATN-21676 | F404: AMT3-087-009 | G404: ATN-21133 | H404: PTCA
A405: 11125795 | B405: 2031018-E-AK | C405: ASAHI Peripheral Guide Wire ASAHI Gladius MG18 PV ES 190cm Pre-shape | D405: 2035006-D | E405: ATN-21676 | F405: AMT3-087-009 | G405: ATN-21133 | H405: PTCA
A406: 11125796 | B406: 2031019-E-AK | C406: ASAHI Peripheral Guide Wire ASAHI Gladius MG18 PV ES 235cm Straight | D406: 2035006-D | E406: ATN-21676 | F406: AMT3-087-009 | G406: ATN-21133 | H406: PTCA
A407: 11125797 | B407: 2031020-E-AK | C407: ASAHI Peripheral Guide Wire ASAHI Gladius MG18 PV ES 235cm Pre-shape | D407: 2035006-D | E407: ATN-21676 | F407: AMT3-087-009 | G407: ATN-21133 | H407: PTCA
A408: 11125798 | B408: 2031021-E-AK | C408: ASAHI Peripheral Guide Wire ASAHI Gladius MG18 PV ES 300cm Straight | D408: 2035006-D | E408: ATN-21676 | F408: AMT3-087-009 | G408: ATN-21133 | H408: PTCA
A409: 11125799 | B409: 2031022-E-AK | C409: ASAHI Peripheral Guide Wire ASAHI Gladius MG18 PV ES 300cm Pre-shape | D409: 2035006-D | E409: ATN-21676 | F409: AMT3-087-009 | G409: ATN-21133 | H409: PTCA
A410: 11121966 | B410: 1556125-H-AK | C410: ASAHI Peripheral Guide Wire Regalia XS 1.0 300cm | D410: 1835166-C | E410: ATN-22142 | F410: AMT3-102-009 | G410: ATN-24851 | H410: PTCA
A411: 11121974 | B411: 1536014-F-AK | C411: ASAHI PTCA Guide Wire Fielder XT-A 300cm | D411: 1835149-C | E411: ATN-22139 | F411: AMT3-162-010 | G411: ATN-25272 | H411: PTCA
A412: 11125732 | B412: 656002-W-A | C412: Streaming 14 165cm | D412: 1935046-B | E412: ATN-19213 | F412: AMT3-130-009 | G412: ATN-24854 | H412: PTCA
A413: 11125733 | B413: 656003-W-A | C413: Streaming 14 180cm | D413: 1935046-B | E413: ATN-19213 | F413: AMT3-130-009 | G413: ATN-24854 | H413: PTCA
A414: 11125734 | B414: 656004-W-A | C414: Streaming 14 180cm Angle | D414: 1935046-B | E414: ATN-19213 | F414: AMT3-130-009 | G414: ATN-24854 | H414: PTCA
A415: 11125737 | B415: 656007-W-A | C415: Streaming 18 165cm | D415: 1935047-B | E415: ATN-19214 | F415: AMT3-132-008 | G415: ATN-24859 | H415: PTCA
A416: 11125738 | B416: 656008-W-A | C416: Streaming 18 180cm | D416: 1935047-B | E416: ATN-19214 | F416: AMT3-132-008 | G416: ATN-24859 | H416: PTCA
A417: 11125626 | B417: 1356020-L-AK | C417: ASAHI Peripheral Guide Wire Treasure Floppy 300cm | D417: 1835191-C | E417: ATN-19042 | F417: AMT3-229-006 | G417: ATN-25448 | H417: PTCA
A418: 11125669 | B418: 1931108-E-AK | C418: ASAHI Peripheral Guide Wire ASAHI Halberd14 Pre-shape 300cm | D418: 1935020-B | E418: ATN-19046 | F418: AMT3-232-006 | G418: ATN-25083 | H418: PTCA
A419: 11126848 | B419: 2231001-B-AK | C419: ASAHI Peripheral Guide Wire ASAHI Gaia PV18 Pre-shape 235cm | D419: 2135121-A | E419: ATN-23653 | F419: AMT3-150-008 | G419: ATN-25030 | H419: PTCA
A420: 11126849 | B420: 2231002-B-AK | C420: ASAHI Peripheral Guide Wire ASAHI Gaia PV18 Pre-shape 300cm | D420: 2135121-A | E420: ATN-23653 | F420: AMT3-150-008 | G420: ATN-25030 | H420: PTCA
A421: 11126850 | B421: 2231003-B-AK | C421: ASAHI Peripheral Guide Wire ASAHI Gaia PV18 Pre-shape 200cm | D421: 2135121-A | E421: ATN-23653 | F421: AMT3-150-008 | G421: ATN-25030 | H421: PTCA
A422: 11126851 | B422: 2231004-B-AK | C422: ASAHI Peripheral Guide Wire ASAHI Gaia PV18 Straight 300cm | D422: 2135121-A | E422: ATN-23653 | F422: AMT3-150-008 | G422: ATN-25030 | H422: PTCA
A423: 11126852 | B423: 2231005-B-AK | C423: ASAHI Peripheral Guide Wire ASAHI Gaia PV18 Straight 200cm | D423: 2135121-A | E423: ATN-23653 | F423: AMT3-150-008 | G423: ATN-25030 | H423: PTCA
A424: 11126853 | B424: 2231006-B-AK | C424: ASAHI Peripheral Guide Wire ASAHI Gaia PV18 Straight 235cm | D424: 2135121-A | E424: ATN-23653 | F424: AMT3-150-008 | G424: ATN-25030 | H424: PTCA
A425: 11126854 | B425: 2231007-B-AK | C425: ASAHI Peripheral Guide Wire Astato XS 20 180cm | D425: 2135122-A | E425: ATN-23654 | F425: AMT3-112-006 | G425: ATN-21815 | H425: PTCA
A426: 11126855 | B426: 2231008-B-AK | C426: ASAHI Peripheral Guide Wire Astato XS 20 300cm | D426: 2135122-A | E426: ATN-23654 | F426: AMT3-112-006 | G426: ATN-21815 | H426: PTCA
...

Sheet Template
A1: Attachment | BF1: Bag | BG1: Box | BI1: JIG | BJ1: 1 | BK1: 2 | BL1: 3 | BM1: 4 | BN1: 5 | BO1: 6 | BP1: 7 | BQ1: 8 | BR1: 9 | BS1: 10 | BT1: 11 | BU1: 12 | BV1: 13 | BW1: 14 | BX1: 15 | BY1: 16 | BZ1: 17 | CA1: 18
BF2: ITEM | BG2: LOT | BH2: Q'TY
A3: QR Code | AF3: 1.Promos system | CC3: ="@1)" -> @1) | CD3: ="@2)" -> @2) | CE3: ="@3)" -> @3) | CF3: ="@4)" -> @4) | CG3: ="@5)" -> @5) | CH3: ="@99)Print" -> @99)Print
AO4: Item Code : | BF4: 1 | BG4: 2 | BH4: Match
AO5: Lot : | BD5: Print | BE5: Product label | BF5: {=INDEX('PTCA Packing 1'!J:J,MATCH($BF3,'PTCA Packing 1'!$B:$B,0),0)} -> #N/A | BG5: {=INDEX('PTCA Packing 1'!K:K,MATCH($BF3,'PTCA Packing 1'!$B:$B,0),0)} -> #N/A | BH5: =$CC$3&BF3&$CD$3&BG3&$CE$3&BF5&$CF$3&BG5&$CH$3 -> #N/A
AO6: Order No : | BE6: Dilator label | BH6: =$CC$3&BF4&$CD$3&BG4&$CE$3&BF6&$CF$3&BG6&$CH$3 -> @1)1@2)2@3) @4)@99)Print
A7: ITEM : | D7: =BF3 -> 0 | L7: LOT : | O7: =BG3 -> 0 | X7: Q'ty : | Z7: =BH3 -> 0 | AD7: Pcs | AO7: Item APS | BE7: Barcoode label | BH7: =$CC$3&BF5&$CD$3&BG5&$CE$3&BF7&$CF$3&BG7&$CH$3 -> #N/A
BE8: Barcode Dilator label | BH8: =$CC$3&BF6&$CD$3&BG6&$CE$3&BF8&$CF$3&BG8&$CH$3 -> @1) @2)@3)@4)@99)Print
A9: 2.Print label process | BE9: CN label | BF9: {=INDEX('PTCA Packing 1'!T:T,MATCH($BF3,'PTCA Packing 1'!$B:$B,0),0)} -> #N/A | BG9: {=INDEX('PTCA Packing 1'!U:U,MATCH($BF3,'PTCA Packing 1'!$B:$B,0),0)} -> #N/A | BH9: =$CC$3&BF7&$CD$3&BG7&$CE$3&BF9&$CF$3&BG9&$CH$3 -> #N/A
A10: Product label (Label check sheet ) | AC10: Dilator label (Label check sheet ) | BE10: KR label | BF10: {=INDEX('PTCA Packing 1'!V:V,MATCH($BF3,'PTCA Packing 1'!$B:$B,0),0)} -> #N/A | BG10: {=INDEX('PTCA Packing 1'!K:K,MATCH($BF3,'PTCA Packing 1'!$B:$B,0),0)} -> #N/A | BH10: =$CC$3&BF8&$CD$3&BG8&$CE$3&BF10&$CF$3&BG10&$CH$3 -> #N/A
A11: Bag | H11: Box | O11: Matching | AC11: Bag | AJ11: Box | AQ11: Matching | BE11: Check Label (Ver.) | BH11: ATN-12346 ver.1.08
BE12: Scan Barcode (Ver.) | BH12: ATN-12346 ver.1.08
V13: Check by | AX13: Check by | BE13: Compare (Ver.) | BH13: ATN-12346 ver.1.08
BD14: Attach label and Seal process | BE14: Item | BF14: =$BF$3 -> 0 | BJ14: {=INDEX('PTCA Packing 1'!Y:Y,MATCH($BF$14,'PTCA Packing 2'!$B:$B,0),0)} -> #N/A | BK14: {=INDEX('PTCA Packing 1'!Z:Z,MATCH($BF$14,'PTCA Packing 2'!$B:$B,0),0)} -> #N/A | BL14: {=INDEX('PTCA Packing 1'!AA:AA,MATCH($BF$14,'PTCA Packing 2'!$B:$B,0),0)} -> #N/A | BM14: {=INDEX('PTCA Packing 1'!AB:AB,MATCH($BF$14,'PTCA Packing 2'!$B:$B,0),0)} -> #N/A | BN14: {=INDEX('PTCA Packing 1'!AC:AC,MATCH($BF$14,'PTCA Packing 2'!$B:$B,0),0)} -> #N/A | BO14: {=INDEX('PTCA Packing 1'!AD:AD,MATCH($BF$14,'PTCA Packing 2'!$B:$B,0),0)} -> #N/A | BP14: {=INDEX('PTCA Packing 1'!AE:AE,MATCH($BF$14,'PTCA Packing 2'!$B:$B,0),0)} -> #N/A | BQ14: {=INDEX('PTCA Packing 1'!AF:AF,MATCH($BF$14,'PTCA Packing 2'!$B:$B,0),0)} -> #N/A | BR14: {=INDEX('PTCA Packing 1'!AG:AG,MATCH($BF$14,'PTCA Packing 2'!$B:$B,0),0)} -> #N/A | BS14: {=INDEX('PTCA Packing 1'!AH:AH,MATCH($BF$14,'PTCA Packing 2'!$B:$B,0),0)} -> #N/A | BT14: {=INDEX('PTCA Packing 1'!AI:AI,MATCH($BF$14,'PTCA Packing 2'!$B:$B,0),0)} -> #N/A | BU14: {=INDEX('PTCA Packing 1'!AJ:AJ,MATCH($BF$14,'PTCA Packing 2'!$B:$B,0),0)} -> #N/A | BV14: {=INDEX('PTCA Packing 1'!AK:AK,MATCH($BF$14,'PTCA Packing 2'!$B:$B,0),0)} -> #N/A | BW14: {=INDEX('PTCA Packing 1'!AL:AL,MATCH($BF$14,'PTCA Packing 2'!$B:$B,0),0)} -> #N/A | BX14: {=INDEX('PTCA Packing 1'!AM:AM,MATCH($BF$14,'PTCA Packing 2'!$B:$B,0),0)} -> #N/A | BY14: {=INDEX('PTCA Packing 1'!AN:AN,MATCH($BF$14,'PTCA Packing 2'!$B:$B,0),0)} -> #N/A | BZ14: {=INDEX('PTCA Packing 1'!AO:AO,MATCH($BF$14,'PTCA Packing 2'!$B:$B,0),0)} -> #N/A | CA14: {=INDEX('PTCA Packing 1'!AP:AP,MATCH($BF$14,'PTCA Packing 2'!$B:$B,0),0)} -> #N/A | CC14: ="@1)" -> @1) | CD14: ="@2)" -> @2) | CE14: ="@3)" -> @3) | CF14: ="@4)" -> @4) | CG14: ="@5)" -> @5) | CH14: ="@6)" -> @6) | CI14: ="@A)" -> @A) | CJ14: ="@B)" -> @B) | CK14: ="@C)" -> @C) | CL14: ="@D)" -> @D) | CM14: ="@E)" -> @E) | CN14: ="@F)" -> @F) | CO14: ="@G)" -> @G) | CP14: ="@H)" -> @H) | CQ14: ="@I)" -> @I) | CR14: ="@99)Attach" -> @99)Attach
A15: =IF($BF$5="","",$BF$5) -> #N/A | H15: =IF($BG$5="","",$BG$5) -> #N/A | AC15: =IF($BF$6="","",$BF$6) | AJ15: =IF($BG$6="","",$BG$6) | BE15: Lot | BF15: =$BG$3 -> 0 | CR15: ="@99)Seal" -> @99)Seal
A16: Barcoode label (Label check sheet ) | AC16: Barcode Dilator label (Label check sheet ) | BE16: Q'ty | BF16: =$BH$3 -> 0
A17: Bag | H17: Box | O17: Matching | AC17: Bag | AJ17: Box | AQ17: Matching | BE17: DW1 | BF17: {=INDEX('PTCA Packing 1'!D:D,MATCH($BF$3,'PTCA Packing 1'!$B:$B,0),0)} -> #N/A
BE18: Packing 1 | BF18: {=INDEX('PTCA Packing 1'!E:E,MATCH($BF$3,'PTCA Packing 1'!$B:$B,0),0)} -> #N/A
V19: Check by | AX19: Check by | BE19: Master SOP | BF19: {=INDEX('PTCA Packing 1'!G:G,MATCH($BF$3,'PTCA Packing 1'!$B:$B,0),0)} -> #N/A
BE20: Holder set | BF20: {=INDEX('PTCA Packing 1'!H:H,MATCH($BF$3,'PTCA Packing 1'!$B:$B,0),0)} -> #N/A
A21: =IF($BF$7="","",$BF$7) | H21: =IF($BG$7="","",$BG$7) | AC21: =IF($BF$8="","",$BF$8) | AJ21: =IF($BG$8="","",$BG$8) | BE21: SOP (Holder set) | BF21: {=INDEX('PTCA Packing 1'!I:I,MATCH($BF$3,'PTCA Packing 1'!$B:$B,0),0)} -> #N/A
A22: CN label (Label check sheet ) | AC22: KR label (Label check sheet ) | BE22: เว้นว่างรอข้อมูล
A23: Bag | H23: Box | O23: Matching | AC23: Bag | AJ23: Box | AQ23: Matching | BE23: เว้นว่างรอข้อมูล
BE24: เว้นว่างรอข้อมูล
V25: Check by | AX25: Check by | BE25: เว้นว่างรอข้อมูล
BE26: Match (attach) 1 | BF26: =CC14&BF14&CD14&BF15&CE14&BF19&CF14&BF17&CG14&BF18&CH14&BF20&CI14&BJ14&CJ14&BK14&CK14&BL14&CL14&BP14&CM14&BQ14&CN14&BR14&CO14&BV14&CP14&BW14&CQ14&BX14&CR14 -> #N/A
A27: =IF($BF$9="","",$BF$9) -> #N/A | H27: =IF($BG$9="","",$BG$9) -> #N/A | AC27: =IF($BF$10="","",$BF$10) -> #N/A | AJ27: =IF($BG$10="","",$BG$10) -> #N/A | BE27: Match (attach) 2 | BF27: =CC14&BF14&CD14&BF15&CE14&BF19&CF14&BF17&CG14&BF18&CH14&BF20&CI14&BM14&CJ14&BN14&CK14&BO14&CL14&BS14&CM14&BT14&CN14&BU14&CO14&BY14&CP14&BZ14&CQ14&CA14&CR14 -> #N/A
BE28: Match (seal) | BF28: =CC14&BF14&CD14&BF15&CE14&BF19&CF14&BF17&CG14&BF18&CH14&BF20&CI14&BJ14&CJ14&BK14&CK14&BL14&CL14&BP14&CM14&BQ14&CN14&BR14&CO14&BV14&CP14&BW14&CQ14&BX14&CR15 -> #N/A
A29: Check Label (Ver.) | K29: Scan Barcode (Ver.) | U29: Compare (Ver.) | BD29: Boxpack | BE29: Item_lot | BF29: =$BF$3&"_"&$BG$3 -> _ | CC29: ="@1)" -> @1) | CD29: ="@2)" -> @2) | CE29: ="@3)" -> @3) | CF29: ="@4)" -> @4) | CG29: ="@5)" -> @5) | CH29: ="@99)Boxpack" -> @99)Boxpack
BE30: item[tab]lot[tab]Q'ty | BF30: =$BF$3&"[tab]"&$BG$3&"[tab]"&BH3 -> [tab][tab] | CC30: Master | CD30: SOP | CE30: DW
BE31: Master SOP[tab]SOP[tab]DW | BF31: =$CC$31&"[tab]"&$CD$31&"[tab]"&CE31 -> #N/A | CC31: {=INDEX('PTCA Packing 2'!G:G,MATCH($BF$3,'PTCA Packing 2'!$B:$B,0),0)} -> #N/A | CD31: {=INDEX('PTCA Packing 2'!E:E,MATCH($BF$3,'PTCA Packing 2'!$B:$B,0),0)} -> #N/A | CE31: {=INDEX('PTCA Packing 2'!D:D,MATCH($BF$3,'PTCA Packing 2'!$B:$B,0),0)} -> #N/A
BE32: เว้นว่างรอข้อมูล
A33: ATN-12346 ver.1.08 | K33: ATN-12346 ver.1.08 | U33: ATN-12346 ver.1.08 | BE33: เว้นว่างรอข้อมูล
BE34: เว้นว่างรอข้อมูล
A35: 3.Attach label and Seal process (Packing 1) | AM35: Matching (Attach) | AV35: Matching (Attach) | BE35: Match | BF35: =CC29&BF3&CD29&BG3&CE29&CC31&CF29&CE31&CG29&CD31&CH29 -> #N/A
A36: Attach label and Seal process
A37: 1.Item | H37: 2.Lot | O37: 3.Q'ty | V37: 4.DW 1 | AC37: 5.Packing 1
AM39: Check by | AV39: Check by
A41: =IF($BF$14="","",$BF$14) -> 0 | H41: =IF($BF$15="","",$BF$15) -> 0 | O41: =IF($BF$16="","",$BF$16) -> 0 | V41: =IF($BF$18="","",$BF$18) -> #N/A | AC41: =IF($BF$18="","",$BF$18) -> #N/A
AV42: Matching (Seal)
...
